[2024-10-19T15:11:59.618+0000] {taskinstance.py:1083} INFO - Dependencies all met for <TaskInstance: ambev_data_quality_pipeline.invalido manual__2024-10-19T15:11:41.482238+00:00 [queued]>
[2024-10-19T15:11:59.625+0000] {taskinstance.py:1083} INFO - Dependencies all met for <TaskInstance: ambev_data_quality_pipeline.invalido manual__2024-10-19T15:11:41.482238+00:00 [queued]>
[2024-10-19T15:11:59.625+0000] {taskinstance.py:1279} INFO - 
--------------------------------------------------------------------------------
[2024-10-19T15:11:59.625+0000] {taskinstance.py:1280} INFO - Starting attempt 1 of 1
[2024-10-19T15:11:59.626+0000] {taskinstance.py:1281} INFO - 
--------------------------------------------------------------------------------
[2024-10-19T15:11:59.635+0000] {taskinstance.py:1300} INFO - Executing <Task(PythonOperator): invalido> on 2024-10-19 15:11:41.482238+00:00
[2024-10-19T15:11:59.639+0000] {standard_task_runner.py:55} INFO - Started process 37172 to run task
[2024-10-19T15:11:59.640+0000] {standard_task_runner.py:82} INFO - Running: ['***', 'tasks', 'run', 'ambev_data_quality_pipeline', 'invalido', 'manual__2024-10-19T15:11:41.482238+00:00', '--job-id', '60', '--raw', '--subdir', 'DAGS_FOLDER/dag_dataquality.py', '--cfg-path', '/tmp/tmpsxvbaqh2']
[2024-10-19T15:11:59.642+0000] {standard_task_runner.py:83} INFO - Job 60: Subtask invalido
[2024-10-19T15:11:59.652+0000] {logging_mixin.py:137} WARNING - /usr/local/lib/python3.9/site-packages/***/settings.py:249 DeprecationWarning: The sql_alchemy_conn option in [core] has been moved to the sql_alchemy_conn option in [database] - the old setting has been used, but please update your config.
[2024-10-19T15:11:59.686+0000] {task_command.py:388} INFO - Running <TaskInstance: ambev_data_quality_pipeline.invalido manual__2024-10-19T15:11:41.482238+00:00 [running]> on host 39b0b1bd9d5a
[2024-10-19T15:11:59.733+0000] {taskinstance.py:1507} INFO - Exporting the following env vars:
AIRFLOW_CTX_DAG_OWNER=Klaus_Rezende
AIRFLOW_CTX_DAG_ID=ambev_data_quality_pipeline
AIRFLOW_CTX_TASK_ID=invalido
AIRFLOW_CTX_EXECUTION_DATE=2024-10-19T15:11:41.482238+00:00
AIRFLOW_CTX_TRY_NUMBER=1
AIRFLOW_CTX_DAG_RUN_ID=manual__2024-10-19T15:11:41.482238+00:00
[2024-10-19T15:11:59.733+0000] {taskinstance.py:1768} ERROR - Task failed with exception
Traceback (most recent call last):
  File "/usr/local/lib/python3.9/site-packages/airflow/operators/python.py", line 175, in execute
    return_value = self.execute_callable()
  File "/usr/local/lib/python3.9/site-packages/airflow/operators/python.py", line 192, in execute_callable
    return self.python_callable(*self.op_args, **self.op_kwargs)
  File "/opt/airflow/dags/dag_dataquality.py", line 38, in error
    raise Exception("Arquivo com erro...")
Exception: Arquivo com erro...
[2024-10-19T15:11:59.742+0000] {taskinstance.py:1318} INFO - Marking task as FAILED. dag_id=ambev_data_quality_pipeline, task_id=invalido, execution_date=20241019T151141, start_date=20241019T151159, end_date=20241019T151159
[2024-10-19T15:11:59.750+0000] {standard_task_runner.py:100} ERROR - Failed to execute job 60 for task invalido (Arquivo com erro...; 37172)
[2024-10-19T15:11:59.772+0000] {local_task_job.py:208} INFO - Task exited with return code 1
[2024-10-19T15:11:59.785+0000] {taskinstance.py:2578} INFO - 0 downstream tasks scheduled from follow-on schedule check
