[2024-10-19T15:06:01.489+0000] {taskinstance.py:1083} INFO - Dependencies all met for <TaskInstance: ambev_data_quality_pipeline.invalido manual__2024-10-19T15:05:43.758232+00:00 [queued]>
[2024-10-19T15:06:01.497+0000] {taskinstance.py:1083} INFO - Dependencies all met for <TaskInstance: ambev_data_quality_pipeline.invalido manual__2024-10-19T15:05:43.758232+00:00 [queued]>
[2024-10-19T15:06:01.497+0000] {taskinstance.py:1279} INFO - 
--------------------------------------------------------------------------------
[2024-10-19T15:06:01.498+0000] {taskinstance.py:1280} INFO - Starting attempt 1 of 1
[2024-10-19T15:06:01.498+0000] {taskinstance.py:1281} INFO - 
--------------------------------------------------------------------------------
[2024-10-19T15:06:01.507+0000] {taskinstance.py:1300} INFO - Executing <Task(PythonOperator): invalido> on 2024-10-19 15:05:43.758232+00:00
[2024-10-19T15:06:01.511+0000] {standard_task_runner.py:55} INFO - Started process 31265 to run task
[2024-10-19T15:06:01.513+0000] {standard_task_runner.py:82} INFO - Running: ['***', 'tasks', 'run', 'ambev_data_quality_pipeline', 'invalido', 'manual__2024-10-19T15:05:43.758232+00:00', '--job-id', '45', '--raw', '--subdir', 'DAGS_FOLDER/dag_dataquality.py', '--cfg-path', '/tmp/tmpv7maie8v']
[2024-10-19T15:06:01.514+0000] {standard_task_runner.py:83} INFO - Job 45: Subtask invalido
[2024-10-19T15:06:01.525+0000] {logging_mixin.py:137} WARNING - /usr/local/lib/python3.9/site-packages/***/settings.py:249 DeprecationWarning: The sql_alchemy_conn option in [core] has been moved to the sql_alchemy_conn option in [database] - the old setting has been used, but please update your config.
[2024-10-19T15:06:01.563+0000] {task_command.py:388} INFO - Running <TaskInstance: ambev_data_quality_pipeline.invalido manual__2024-10-19T15:05:43.758232+00:00 [running]> on host 39b0b1bd9d5a
[2024-10-19T15:06:01.612+0000] {taskinstance.py:1507} INFO - Exporting the following env vars:
AIRFLOW_CTX_DAG_OWNER=Klaus_Rezende
AIRFLOW_CTX_DAG_ID=ambev_data_quality_pipeline
AIRFLOW_CTX_TASK_ID=invalido
AIRFLOW_CTX_EXECUTION_DATE=2024-10-19T15:05:43.758232+00:00
AIRFLOW_CTX_TRY_NUMBER=1
AIRFLOW_CTX_DAG_RUN_ID=manual__2024-10-19T15:05:43.758232+00:00
[2024-10-19T15:06:01.612+0000] {taskinstance.py:1768} ERROR - Task failed with exception
Traceback (most recent call last):
  File "/usr/local/lib/python3.9/site-packages/airflow/operators/python.py", line 175, in execute
    return_value = self.execute_callable()
  File "/usr/local/lib/python3.9/site-packages/airflow/operators/python.py", line 192, in execute_callable
    return self.python_callable(*self.op_args, **self.op_kwargs)
  File "/opt/airflow/dags/dag_dataquality.py", line 38, in error
    raise Exception("Arquivo com erro...")
Exception: Arquivo com erro...
[2024-10-19T15:06:01.621+0000] {taskinstance.py:1318} INFO - Marking task as FAILED. dag_id=ambev_data_quality_pipeline, task_id=invalido, execution_date=20241019T150543, start_date=20241019T150601, end_date=20241019T150601
[2024-10-19T15:06:01.629+0000] {standard_task_runner.py:100} ERROR - Failed to execute job 45 for task invalido (Arquivo com erro...; 31265)
[2024-10-19T15:06:01.645+0000] {local_task_job.py:208} INFO - Task exited with return code 1
[2024-10-19T15:06:01.658+0000] {taskinstance.py:2578} INFO - 0 downstream tasks scheduled from follow-on schedule check
